<?xml version="1.0"?>

<robot xmlns:xacro="http://www.ros.org/wiki/xacro">
    <!-- some constants -->
    <xacro:property name="PI" value="3.1415926535897931"/>
    <xacro:property name="joint_damping" value="10.0"/>
    <xacro:property name="joint_friction" value="0.1"/>
    <xacro:property name="max_effort" value="100"/>
    <xacro:property name="max_velocity" value="10"/>
     <!-- joint limits -->
  <xacro:property name="joint_limit_1" value="170"/>
  <xacro:property name="joint_limit_2" value="120"/>
  <xacro:property name="joint_limit_3" value="170"/>
  <xacro:property name="joint_limit_4" value="120"/>
  <xacro:property name="joint_limit_5" value="170"/>
  <xacro:property name="joint_limit_6" value="120"/>
  <xacro:property name="joint_limit_7" value="175"/>
  <!-- max torques per joint -->
  <xacro:property name="max_effort_1" value="176"/>
  <xacro:property name="max_effort_2" value="176"/>
  <xacro:property name="max_effort_3" value="110"/>
  <xacro:property name="max_effort_4" value="110"/>
  <xacro:property name="max_effort_5" value="110"/>
  <xacro:property name="max_effort_6" value="40"/>
  <xacro:property name="max_effort_7" value="40"/>
  <!-- max velocities per joint -->
  <xacro:property name="max_velocity_1" value="${0.1*98 * PI / 180.}"/>
  <xacro:property name="max_velocity_2" value="${0.1*98 * PI / 180.}"/>
  <xacro:property name="max_velocity_3" value="${0.1*100 * PI / 180.}"/>
  <xacro:property name="max_velocity_4" value="${0.1*130 * PI / 180.}"/>
  <xacro:property name="max_velocity_5" value="${0.1*140 * PI / 180.}"/>
  <xacro:property name="max_velocity_6" value="${0.1*PI}"/>
  <xacro:property name="max_velocity_7" value="${0.1*PI}"/>
  <xacro:property name="safety_controller_k_pos" value="100"/>
  <xacro:property name="safety_controller_k_vel" value="10"/>
  <xacro:property name="safety_percentage" value="0.95"/>
    <!-- includes -->
    <!-- robot as extracted via https://github.com/syuntoku14/fusion2urdf -->
    <xacro:macro name="med7" params="parent:=^|world robot_name:=^|lbr sim:=^|true">

        <!--joint between {parent} and link_0-->
        <joint name="${parent}_${robot_name}_joint" type="fixed">
            <parent link="${parent}"/>
            <child link="${robot_name}_link_0"/>
        </joint>

        <link name="${robot_name}_link_0">
            <inertial>
            <origin rpy="0 0 0" xyz="-0.1 0 0.07"/>
            <mass value="5"/>
            <inertia ixx="0.05"  ixy="0"  ixz="0" iyy="0.06" iyz="0" izz="0.03" />
            </inertial>
            <visual>
            <origin rpy="0 0 0" xyz="0 0 0"/>
            <geometry>
                <mesh filename="$(cwd)/kuka_iiwa/meshes/iiwa7/visual/link_0.stl"/>
            </geometry>
            </visual>
            <collision>
            <origin rpy="0 0 0" xyz="0 0 0"/>
            <geometry>
                <mesh filename="$(cwd)/kuka_iiwa/meshes/iiwa7/collision/link_0.stl"/>
            </geometry>
            </collision>
        </link>
        <!-- joint between link_0 and link_1 -->
        <joint name="${robot_name}_joint_1" type="revolute">
          <parent link="${robot_name}_link_0"/>
          <child link="${robot_name}_link_1"/>
          <origin xyz="0 0 0.15" rpy="0 0 0"/>
          <axis xyz="0 0 1"/>
          <limit lower="${-joint_limit_1 * PI / 180}" upper="${joint_limit_1 * PI / 180}"
                 effort="${max_effort_1}" velocity="${max_velocity_1}" />
          <dynamics damping="${joint_damping}"/>
        </joint>

        <link name="${robot_name}_link_1">
          <inertial>
            <origin xyz="0 -0.03 0.12" rpy="0 0 0"/>
            <mass value="3.4525"/>
            <inertia ixx="0.02183"  ixy="0"  ixz="0" iyy="0.007703" iyz="-0.003887" izz="0.02083" />
          </inertial>
          <visual>
            <origin xyz="0 0 0.0075" rpy="0 0 0"/>
            <geometry>
              <mesh filename="$(cwd)/kuka_iiwa/meshes/iiwa7/visual/link_1.stl"/>
            </geometry>
          </visual>
          <collision>
            <origin xyz="0 0 0.0075" rpy="0 0 0"/>
            <geometry>
              <mesh filename="$(cwd)/kuka_iiwa/meshes/iiwa7/collision/link_1.stl"/>
            </geometry>
          </collision>
        </link>

        <joint name="${robot_name}_joint_2" type="revolute">
          <parent link="${robot_name}_link_1"/>
          <child link="${robot_name}_link_2"/>
          <origin xyz="0 0 0.19" rpy="${PI / 2}   0 ${PI}"/>
          <axis xyz="0 0 1"/>
          <limit lower="${-joint_limit_2 * PI / 180}" upper="${joint_limit_2 * PI / 180}"
                 effort="${max_effort_2}" velocity="${max_velocity_2}" />
          <dynamics damping="${joint_damping}"/>
        </joint>

        <link name="${robot_name}_link_2">
          <inertial>
            <origin xyz="0.0003 0.059 0.042" rpy="0 0 0"/>
            <mass value="3.4821"/>
            <inertia ixx="0.02076"  ixy="0"  ixz="-0.003626" iyy="0.02179" iyz="0" izz="0.00779" />
          </inertial>
          <visual>
            <origin xyz="0 0 0" rpy="0 0 0"/>
            <geometry>
              <mesh filename="$(cwd)/kuka_iiwa/meshes/iiwa7/visual/link_2.stl"/>
            </geometry>
          </visual>

          <collision>
            <origin xyz="0 0 0" rpy="0 0 0"/>
            <geometry>
              <mesh filename="$(cwd)/kuka_iiwa/meshes/iiwa7/collision/link_2.stl"/>
            </geometry>
          </collision>
        </link>

        <joint name="${robot_name}_joint_3" type="revolute">
          <parent link="${robot_name}_link_2"/>
          <child link="${robot_name}_link_3"/>
          <origin xyz="0 0.21 0" rpy="${PI / 2} 0 ${PI}"/>
          <axis xyz="0 0 1"/>
          <limit lower="${-joint_limit_3 * PI / 180}" upper="${joint_limit_3 * PI / 180}"
                 effort="${max_effort_3}" velocity="${max_velocity_3}" />
          <dynamics damping="${joint_damping}"/>
        </joint>

        <link name="${robot_name}_link_3">
          <inertial>
            <origin xyz="0 0.03 0.13" rpy="0 0 0"/>
            <mass value="4.05623"/>
            <inertia ixx="0.03204"  ixy="0"  ixz="0" iyy="0.00972" iyz="0.006227" izz="0.03042" />
          </inertial>

          <visual>
            <origin xyz="0 0 -0.026" rpy="0 0 0"/>
            <geometry>
              <mesh filename="$(cwd)/kuka_iiwa/meshes/iiwa7/visual/link_3.stl"/>
            </geometry>
          </visual>

          <collision>
            <origin xyz="0 0 -0.026" rpy="0 0 0"/>
            <geometry>
              <mesh filename="$(cwd)/kuka_iiwa/meshes/iiwa7/collision/link_3.stl"/>
            </geometry>
          </collision>

        </link>

        <joint name="${robot_name}_joint_4" type="revolute">
          <parent link="${robot_name}_link_3"/>
          <child link="${robot_name}_link_4"/>
          <origin xyz="0 0 0.19" rpy="${PI / 2} 0 0"/>
          <axis xyz="0 0 1"/>
          <limit lower="${-joint_limit_4 * PI / 180}" upper="${joint_limit_4 * PI / 180}"
                 effort="${max_effort_4}" velocity="${max_velocity_4}" />

          <dynamics damping="${joint_damping}"/>
        </joint>

        <link name="${robot_name}_link_4">
          <inertial>
            <origin xyz="0 0.067 0.034" rpy="0 0 0"/>
            <mass value="3.4822"/>
            <inertia ixx="0.02178"  ixy="0"  ixz="0" iyy="0.02075" iyz="-0.003625" izz="0.007785" />
          </inertial>

          <visual>
            <origin xyz="0 0 0" rpy="0 0 0"/>
            <geometry>
              <mesh filename="$(cwd)/kuka_iiwa/meshes/iiwa7/visual/link_4.stl"/>
            </geometry>
          </visual>

          <collision>
            <origin xyz="0 0 0" rpy="0 0 0"/>
            <geometry>
              <mesh filename="$(cwd)/kuka_iiwa/meshes/iiwa7/collision/link_4.stl"/>
            </geometry>
          </collision>
        </link>

        <joint name="${robot_name}_joint_5" type="revolute">
          <parent link="${robot_name}_link_4"/>
          <child link="${robot_name}_link_5"/>
          <origin xyz="0 0.21 0" rpy="${-PI / 2} ${PI} 0"/>
          <axis xyz="0 0 1"/>
          <limit lower="${-joint_limit_5 * PI / 180}" upper="${joint_limit_5 * PI / 180}"
                 effort="${max_effort_5}" velocity="${max_velocity_5}" />
          <dynamics damping="${joint_damping}"/>
        </joint>

        <link name="${robot_name}_link_5">
          <inertial>
            <origin xyz="0.0001 0.021 0.076" rpy="0 0 0"/>
            <mass value="2.1633"/>
            <inertia ixx="0.01287"  ixy="0"  ixz="0" iyy="0.005708" iyz="-0.003946" izz="0.01112" />
          </inertial>

          <visual>
            <origin xyz="0 0 -0.026" rpy="0 0 0"/>
            <geometry>
              <mesh filename="$(cwd)/kuka_iiwa/meshes/iiwa7/visual/link_5.stl"/>
            </geometry>
          </visual>

          <collision>
            <origin xyz="0 0 -0.026" rpy="0 0 0"/>
            <geometry>
              <mesh filename="$(cwd)/kuka_iiwa/meshes/iiwa7/collision/link_5.stl"/>
            </geometry>
          </collision>
        </link>

        <joint name="${robot_name}_joint_6" type="revolute">
          <parent link="${robot_name}_link_5"/>
          <child link="${robot_name}_link_6"/>
          <origin xyz="0 0.06070 0.19" rpy="${PI / 2} 0 0"/>
          <axis xyz="0 0 1"/>
          <limit lower="${-joint_limit_6 * PI / 180}" upper="${joint_limit_6 * PI / 180}"
                 effort="${max_effort_6}" velocity="${max_velocity_6}" />
          <dynamics damping="${joint_damping}"/>
        </joint>

        <link name="${robot_name}_link_6">
          <inertial>
            <origin xyz="0 0.0006 0.0004" rpy="0 0 0"/>
            <mass value="2.3466"/>
            <inertia ixx="0.006509"  ixy="0"  ixz="0" iyy="0.006259" iyz="0.00031891" izz="0.004527" />
          </inertial>

          <visual>
            <origin xyz="0 0 0" rpy="0 0 0"/>
            <geometry>
              <mesh filename="$(cwd)/kuka_iiwa/meshes/iiwa7/visual/link_6.stl"/>
            </geometry>
          </visual>

          <collision>
            <origin xyz="0 0 0" rpy="0 0 0"/>
            <geometry>
              <mesh filename="$(cwd)/kuka_iiwa/meshes/iiwa7/collision/link_6.stl"/>
            </geometry>
          </collision>
        </link>

        <joint name="${robot_name}_joint_7" type="revolute">
          <parent link="${robot_name}_link_6"/>
          <child link="${robot_name}_link_7"/>
          <origin xyz="0 0.081 0.06070" rpy="${- PI / 2} ${PI} 0"/>
          <axis xyz="0 0 1"/>
          <limit lower="${-joint_limit_7 * PI / 180}" upper="${joint_limit_7 * PI / 180}"
                 effort="${max_effort_7}" velocity="${max_velocity_7}" />
          <dynamics damping="${joint_damping}"/>
        </joint>

        <link name="${robot_name}_link_7">
          <inertial>
            <origin xyz="0 0 0.02" rpy="0 0 0"/>
            <mass value="3.129"/>
            <inertia ixx="0.01464"  ixy="0.0005912"  ixz="0" iyy="0.01465" iyz="0" izz="0.002872" />
          </inertial>

          <visual>
            <origin xyz="0 0 -0.0005" rpy="0 0 0"/>
            <geometry>
              <mesh filename="$(cwd)/kuka_iiwa/meshes/iiwa7/visual/link_7-MF-Touch-pneumatisch.stl"/>
            </geometry>
          </visual>

          <collision>
            <origin xyz="0 0 -0.0005" rpy="0 0 0"/>
            <geometry>
              <mesh filename="$(cwd)/kuka_iiwa/meshes/iiwa7/collision/link_7-MF-Touch-pneumatisch.stl"/>
            </geometry>
          </collision>
        </link>

        <joint name="${robot_name}_joint_ee" type="fixed">
            <parent link="${robot_name}_link_7"/>
            <child link="${robot_name}_link_ee"/>
            <origin xyz="0 0 0.035" rpy="0 0 0"/>
        </joint>
        
        <link name="${robot_name}_link_ee">
        </link>

        <!-- <xacro:med_gazebo robot_name="${robot_name}"/> -->
        <!-- TODO: move modes to args, decouple urdf/gazebo/controls -->
        <!-- add notice for remote host to set to kuka controller -->
        <!-- <xacro:lbr_hardware_interface sim="${sim}" remote_host="INADDR_ANY" port="30200" robot_name="${robot_name}"/> -->

    </xacro:macro>
</robot>
