<?xml version="1.0"?>
<!--|
    Copyright (C) 2019-2022 Learning Algorithms and Systems Laboratory, EPFL, Switzerland
    Authors:  Konstantinos Chatzilygeroudis (maintainer)
              Matthias Mayr
              Bernardo Fichera
    email:    costashatz@gmail.com
              matthias.mayr@cs.lth.se
              bernardo.fichera@epfl.ch
    Other contributors:
              Yoan Mollard (yoan@aubrune.eu)
              Walid Amanhoud (walid.amanhoud@epfl.ch)
    website:  lasa.epfl.ch

    This file is part of iiwa_ros.

    iiwa_ros is free software: you can redistribute it and/or modify
    it under the terms of the GNU General Public License as published by
    the Free Software Foundation, either version 3 of the License, or
    (at your option) any later version.

    iiwa_ros is distributed in the hope that it will be useful,
    but WITHOUT ANY WARRANTY; without even the implied warranty of
    MERCHANTABILITY or FITNESS FOR A PARTICULAR PURPOSE.  See the
    GNU General Public License for more details.

|-->
<robot xmlns:xacro="http://www.ros.org/wiki/xacro">

  <!-- Import all Gazebo-customization elements, including Gazebo colors -->
  <xacro:include filename="iiwa.gazebo.xacro" />
  <!-- Import Transmissions -->
  <xacro:include filename="iiwa.transmission.xacro" />
  <!-- Include Utilities -->
  <xacro:include filename="utilities.xacro" />

  <!-- some parameters -->
  <xacro:property name="safety" value="true"/>

  <!-- some constants -->
  <xacro:property name="safety_controller_k_pos" value="100"/>
  <xacro:property name="safety_controller_k_vel" value="10"/>
  <xacro:property name="safety_percentage" value="0.95"/>
  <xacro:property name="joint_damping" value="0.5"/>
  <!-- joint limits -->
  <xacro:property name="joint_limit_1" value="170"/>
  <xacro:property name="joint_limit_2" value="120"/>
  <xacro:property name="joint_limit_3" value="170"/>
  <xacro:property name="joint_limit_4" value="120"/>
  <xacro:property name="joint_limit_5" value="170"/>
  <xacro:property name="joint_limit_6" value="120"/>
  <xacro:property name="joint_limit_7" value="175"/>
  <!-- max torques per joint -->
  <xacro:property name="max_effort_1" value="176"/>
  <xacro:property name="max_effort_2" value="176"/>
  <xacro:property name="max_effort_3" value="110"/>
  <xacro:property name="max_effort_4" value="110"/>
  <xacro:property name="max_effort_5" value="110"/>
  <xacro:property name="max_effort_6" value="40"/>
  <xacro:property name="max_effort_7" value="40"/>
  <!-- max velocities per joint -->
  <xacro:property name="max_velocity_1" value="${0.1*98 * PI / 180.}"/>
  <xacro:property name="max_velocity_2" value="${0.1*98 * PI / 180.}"/>
  <xacro:property name="max_velocity_3" value="${0.1*100 * PI / 180.}"/>
  <xacro:property name="max_velocity_4" value="${0.1*130 * PI / 180.}"/>
  <xacro:property name="max_velocity_5" value="${0.1*140 * PI / 180.}"/>
  <xacro:property name="max_velocity_6" value="${0.1*PI}"/>
  <xacro:property name="max_velocity_7" value="${0.1*PI}"/>

  <xacro:macro name="iiwa7" params="parent hardware_interface robot_name collision_postfix *origin">

    <!--joint between {parent} and link_0-->
    <joint name="${parent}_${robot_name}_joint" type="fixed">
      <xacro:insert_block name="origin"/>
      <parent link="${parent}"/>
      <child link="${robot_name}_link_0"/>
    </joint>

    <link name="${robot_name}_link_0">
      <inertial>
        <origin xyz="-0.1 0 0.07" rpy="0 0 0"/>
        <mass value="5"/>
        <inertia ixx="0.05"  ixy="0"  ixz="0" iyy="0.06" iyz="0" izz="0.03" />
      </inertial>

      <visual>
        <origin xyz="0 0 0" rpy="0 0 0"/>
        <geometry>
          <mesh filename="$(cwd)/kuka_iiwa/meshes/iiwa7/visual/link_0.stl"/>
        </geometry>
        <material name="Grey"/>
      </visual>

      <collision>
        <origin xyz="0 0 0" rpy="0 0 0"/>
        <geometry>
          <mesh filename="$(cwd)/kuka_iiwa/meshes/iiwa7/collision/link_0.stl"/>
        </geometry>
        <material name="Grey"/>
      </collision>

      <self_collision_checking>
        <origin xyz="0 0 0" rpy="0 0 0"/>
        <geometry>
          <capsule radius="0.15" length="0.25"/>
        </geometry>
      </self_collision_checking>

    </link>

    <!-- joint between link_0 and link_1 -->
    <joint name="${robot_name}_joint_1" type="revolute">
      <parent link="${robot_name}_link_0"/>
      <child link="${robot_name}_link_1"/>
      <origin xyz="0 0 0.15" rpy="0 0 0"/>
      <axis xyz="0 0 1"/>
      <limit lower="${-joint_limit_1 * PI / 180}" upper="${joint_limit_1 * PI / 180}"
             effort="${max_effort_1}" velocity="${max_velocity_1}" />
      <xacro:safe_controller safety="${safety}"
                               lower="${-safety_percentage * joint_limit_1 * PI / 180}"
                               upper="${safety_percentage * joint_limit_1 * PI / 180}"
                               k_p="${safety_controller_k_pos}"
                               k_v="${safety_controller_k_vel}"/>
      <dynamics damping="${joint_damping}"/>
    </joint>

    <link name="${robot_name}_link_1">
      <inertial>
        <origin xyz="0 -0.03 0.12" rpy="0 0 0"/>
        <mass value="3.4525"/>
        <inertia ixx="0.02183"  ixy="0"  ixz="0" iyy="0.007703" iyz="-0.003887" izz="0.02083" />
      </inertial>
      <visual>
        <origin xyz="0 0 0.0075" rpy="0 0 0"/>
        <geometry>
          <mesh filename="$(cwd)/kuka_iiwa/meshes/iiwa7/visual/link_1.stl"/>
        </geometry>
        <material name="Orange"/>
      </visual>
      <collision>
        <origin xyz="0 0 0.0075" rpy="0 0 0"/>
        <geometry>
          <mesh filename="$(cwd)/kuka_iiwa/meshes/iiwa7/collision/link_1.stl"/>
        </geometry>
        <material name="Orange"/>
      </collision>
    </link>

    <joint name="${robot_name}_joint_2" type="revolute">
      <parent link="${robot_name}_link_1"/>
      <child link="${robot_name}_link_2"/>
      <origin xyz="0 0 0.19" rpy="${PI / 2}   0 ${PI}"/>
      <axis xyz="0 0 1"/>
      <limit lower="${-joint_limit_2 * PI / 180}" upper="${joint_limit_2 * PI / 180}"
             effort="${max_effort_2}" velocity="${max_velocity_2}" />
      <xacro:safe_controller safety="${safety}"
                               lower="${-safety_percentage * joint_limit_2 * PI / 180}"
                               upper="${safety_percentage * joint_limit_2 * PI / 180}"
                               k_p="${safety_controller_k_pos}"
                               k_v="${safety_controller_k_vel}"/>
      <dynamics damping="${joint_damping}"/>
    </joint>

    <link name="${robot_name}_link_2">
      <inertial>
        <origin xyz="0.0003 0.059 0.042" rpy="0 0 0"/>
        <mass value="3.4821"/>
        <inertia ixx="0.02076"  ixy="0"  ixz="-0.003626" iyy="0.02179" iyz="0" izz="0.00779" />
      </inertial>
      <visual>
        <origin xyz="0 0 0" rpy="0 0 0"/>
        <geometry>
          <mesh filename="$(cwd)/kuka_iiwa/meshes/iiwa7/visual/link_2.stl"/>
        </geometry>
        <material name="Orange"/>
      </visual>

      <collision>
        <origin xyz="0 0 0" rpy="0 0 0"/>
        <geometry>
          <mesh filename="$(cwd)/kuka_iiwa/meshes/iiwa7/collision/link_2.stl"/>
        </geometry>
        <material name="Orange"/>
      </collision>
    </link>

    <joint name="${robot_name}_joint_3" type="revolute">
      <parent link="${robot_name}_link_2"/>
      <child link="${robot_name}_link_3"/>
      <origin xyz="0 0.21 0" rpy="${PI / 2} 0 ${PI}"/>
      <axis xyz="0 0 1"/>
      <limit lower="${-joint_limit_3 * PI / 180}" upper="${joint_limit_3 * PI / 180}"
             effort="${max_effort_3}" velocity="${max_velocity_3}" />
      <xacro:safe_controller safety="${safety}"
                               lower="${-safety_percentage * joint_limit_3 * PI / 180}"
                               upper="${safety_percentage * joint_limit_3 * PI / 180}"
                               k_p="${safety_controller_k_pos}"
                               k_v="${safety_controller_k_vel}"/>
      <dynamics damping="${joint_damping}"/>
    </joint>

    <link name="${robot_name}_link_3">
      <inertial>
        <origin xyz="0 0.03 0.13" rpy="0 0 0"/>
        <mass value="4.05623"/>
        <inertia ixx="0.03204"  ixy="0"  ixz="0" iyy="0.00972" iyz="0.006227" izz="0.03042" />
      </inertial>

      <visual>
        <origin xyz="0 0 -0.026" rpy="0 0 0"/>
        <geometry>
          <mesh filename="$(cwd)/kuka_iiwa/meshes/iiwa7/visual/link_3.stl"/>
        </geometry>
        <material name="Orange"/>
      </visual>

      <collision>
        <origin xyz="0 0 -0.026" rpy="0 0 0"/>
        <geometry>
          <mesh filename="$(cwd)/kuka_iiwa/meshes/iiwa7/collision/link_3.stl"/>
        </geometry>
        <material name="Orange"/>
      </collision>

    </link>

    <joint name="${robot_name}_joint_4" type="revolute">
      <parent link="${robot_name}_link_3"/>
      <child link="${robot_name}_link_4"/>
      <origin xyz="0 0 0.19" rpy="${PI / 2} 0 0"/>
      <axis xyz="0 0 1"/>
      <limit lower="${-joint_limit_4 * PI / 180}" upper="${joint_limit_4 * PI / 180}"
             effort="${max_effort_4}" velocity="${max_velocity_4}" />
      <xacro:safe_controller safety="${safety}"
                               lower="${-safety_percentage * joint_limit_4 * PI / 180}"
                               upper="${safety_percentage * joint_limit_4 * PI / 180}"
                               k_p="${safety_controller_k_pos}"
                               k_v="${safety_controller_k_vel}"/>
      <dynamics damping="${joint_damping}"/>
    </joint>

    <link name="${robot_name}_link_4">
      <inertial>
        <origin xyz="0 0.067 0.034" rpy="0 0 0"/>
        <mass value="3.4822"/>
        <inertia ixx="0.02178"  ixy="0"  ixz="0" iyy="0.02075" iyz="-0.003625" izz="0.007785" />
      </inertial>

      <visual>
        <origin xyz="0 0 0" rpy="0 0 0"/>
        <geometry>
          <mesh filename="$(cwd)/kuka_iiwa/meshes/iiwa7/visual/link_4.stl"/>
        </geometry>
        <material name="Orange"/>
      </visual>

      <collision>
        <origin xyz="0 0 0" rpy="0 0 0"/>
        <geometry>
          <mesh filename="$(cwd)/kuka_iiwa/meshes/iiwa7/collision/link_4.stl"/>
        </geometry>
        <material name="Orange"/>
      </collision>
    </link>

    <joint name="${robot_name}_joint_5" type="revolute">
      <parent link="${robot_name}_link_4"/>
      <child link="${robot_name}_link_5"/>
      <origin xyz="0 0.21 0" rpy="${-PI / 2} ${PI} 0"/>
      <axis xyz="0 0 1"/>
      <limit lower="${-joint_limit_5 * PI / 180}" upper="${joint_limit_5 * PI / 180}"
             effort="${max_effort_5}" velocity="${max_velocity_5}" />
      <xacro:safe_controller safety="${safety}"
                               lower="${-safety_percentage * joint_limit_5 * PI / 180}"
                               upper="${safety_percentage * joint_limit_5 * PI / 180}"
                               k_p="${safety_controller_k_pos}"
                               k_v="${safety_controller_k_vel}"/>
      <dynamics damping="${joint_damping}"/>
    </joint>

    <link name="${robot_name}_link_5">
      <inertial>
        <origin xyz="0.0001 0.021 0.076" rpy="0 0 0"/>
        <mass value="2.1633"/>
        <inertia ixx="0.01287"  ixy="0"  ixz="0" iyy="0.005708" iyz="-0.003946" izz="0.01112" />
      </inertial>

      <visual>
        <origin xyz="0 0 -0.026" rpy="0 0 0"/>
        <geometry>
          <mesh filename="$(cwd)/kuka_iiwa/meshes/iiwa7/visual/link_5.stl"/>
        </geometry>
        <material name="Orange"/>
      </visual>

      <collision>
        <origin xyz="0 0 -0.026" rpy="0 0 0"/>
        <geometry>
          <mesh filename="$(cwd)/kuka_iiwa/meshes/iiwa7/collision/link_5.stl"/>
        </geometry>
        <material name="Orange"/>
      </collision>
    </link>

    <joint name="${robot_name}_joint_6" type="revolute">
      <parent link="${robot_name}_link_5"/>
      <child link="${robot_name}_link_6"/>
      <origin xyz="0 0.06070 0.19" rpy="${PI / 2} 0 0"/>
      <axis xyz="0 0 1"/>
      <limit lower="${-joint_limit_6 * PI / 180}" upper="${joint_limit_6 * PI / 180}"
             effort="${max_effort_6}" velocity="${max_velocity_6}" />
      <xacro:safe_controller safety="${safety}"
                               lower="${-safety_percentage * joint_limit_6 * PI / 180}"
                               upper="${safety_percentage * joint_limit_6 * PI / 180}"
                               k_p="${safety_controller_k_pos}"
                               k_v="${safety_controller_k_vel}"/>
      <dynamics damping="${joint_damping}"/>
    </joint>

    <link name="${robot_name}_link_6">
      <inertial>
        <origin xyz="0 0.0006 0.0004" rpy="0 0 0"/>
        <mass value="2.3466"/>
        <inertia ixx="0.006509"  ixy="0"  ixz="0" iyy="0.006259" iyz="0.00031891" izz="0.004527" />
      </inertial>

      <visual>
        <origin xyz="0 0 0" rpy="0 0 0"/>
        <geometry>
          <mesh filename="$(cwd)/kuka_iiwa/meshes/iiwa7/visual/link_6.stl"/>
        </geometry>
        <material name="Orange"/>
      </visual>

      <collision>
        <origin xyz="0 0 0" rpy="0 0 0"/>
        <geometry>
          <mesh filename="$(cwd)/kuka_iiwa/meshes/iiwa7/collision/link_6.stl"/>
        </geometry>
        <material name="Orange"/>
      </collision>
    </link>

    <joint name="${robot_name}_joint_7" type="revolute">
      <parent link="${robot_name}_link_6"/>
      <child link="${robot_name}_link_7"/>
      <origin xyz="0 0.081 0.06070" rpy="${- PI / 2} ${PI} 0"/>
      <axis xyz="0 0 1"/>
      <limit lower="${-joint_limit_7 * PI / 180}" upper="${joint_limit_7 * PI / 180}"
             effort="${max_effort_7}" velocity="${max_velocity_7}" />
      <xacro:safe_controller safety="${safety}"
                               lower="${-safety_percentage * joint_limit_7 * PI / 180}"
                               upper="${safety_percentage * joint_limit_7 * PI / 180}"
                               k_p="${safety_controller_k_pos}"
                               k_v="${safety_controller_k_vel}"/>
      <dynamics damping="${joint_damping}"/>
    </joint>

    <link name="${robot_name}_link_7">
      <inertial>
        <origin xyz="0 0 0.02" rpy="0 0 0"/>
        <mass value="3.129"/>
        <inertia ixx="0.01464"  ixy="0.0005912"  ixz="0" iyy="0.01465" iyz="0" izz="0.002872" />
      </inertial>

      <visual>
        <origin xyz="0 0 -0.0005" rpy="0 0 0"/>
        <geometry>
          <mesh filename="$(cwd)/kuka_iiwa/meshes/iiwa7/visual/link_7-MF-Touch-pneumatisch.stl"/>
        </geometry>
        <material name="Grey"/>
      </visual>

      <collision>
        <origin xyz="0 0 -0.0005" rpy="0 0 0"/>
        <geometry>
          <mesh filename="$(cwd)/kuka_iiwa/meshes/iiwa7/collision/link_7-MF-Touch-pneumatisch.stl"/>
        </geometry>
        <material name="Grey"/>
      </collision>
    </link>
 
   <!--
  <joint name="${robot_name}_joint_force_torque" type="fixed">
      <parent link="${robot_name}_link_7"/>
      <child link="${robot_name}_sensor_adapter_link"/>
      <origin xyz="0 0 0.07" rpy="0 0 0"/>
    </joint>
    <link name="${robot_name}_sensor_adapter_link">
      <inertial>
        <origin
          xyz="-0.0032699 0.0005979 0.021544"
          rpy="0 0 0" />
        <mass
          value="0.26" />
        <inertia
          ixx="5.7118E-05"
          ixy="-1.8065E-08"
          ixz="4.0016E-08"
          iyy="5.7024E-05"
          iyz="2.6993E-08"
          izz="9.712E-05" />
      </inertial>
      <visual>
        <origin
          xyz="0 0 0"
          rpy="0 0 0" />
        <geometry>
          <mesh
            filename="$(cwd)/kuka_iiwa/../ft_sensor/meshes/sensor_adapter_link.STL" />
        </geometry>
        <material
          name="">
          <color
            rgba="0.79216 0.81961 0.93333 1" />
        </material>
      </visual>
      <collision>
        <origin
          xyz="0 0 0"
          rpy="0 0 0" />
        <geometry>
          <mesh
            filename="$(cwd)/kuka_iiwa/../ft_sensor/meshes/sensor_adapter_link.STL" />
        </geometry>
      </collision>
    </link>

-->
    <!-- Actual end effector 
    <joint name="${robot_name}_end_effector" type="fixed">
      <parent link="${robot_name}_sensor_adapter_link"/>
      <child link="${robot_name}_ee_link"/>
      <origin xyz="0 0 0.04" rpy="0 0 0"/>
    </joint>
        <link name="${robot_name}_ee_link"> -->
      <!-- <visual>
        <origin
          xyz="0 0 0"
          rpy="0 0 0" />
        <geometry>
          <sphere radius="0.01"/>
        </geometry>
        <material
          name="">
          <color
            rgba="0.79216 0.81961 0.93333 1" />
        </material>
      </visual>
    </link>-->
  

   <!-- <gazebo reference="${robot_name}_joint_1">
      <provideFeedback>true</provideFeedback>
    </gazebo>
    <gazebo>
      <plugin name="ft_sensor_plugin" filename="libgazebo_ros_ft_sensor.so">
        <updateRate>100</updateRate>
        <topicName>ft_sensor/joint_1</topicName>
        <gaussianNoise>0.0</gaussianNoise>
        <jointName>${robot_name}_joint_1</jointName>
      </plugin>
    </gazebo>

    <gazebo reference="${robot_name}_joint_2">
      <provideFeedback>true</provideFeedback>
    </gazebo>
    <gazebo>
      <plugin name="ft_sensor_plugin" filename="libgazebo_ros_ft_sensor.so">
        <updateRate>100</updateRate>
        <topicName>ft_sensor/joint_2</topicName>
        <gaussianNoise>0.0</gaussianNoise>
        <jointName>${robot_name}_joint_2</jointName>
      </plugin>
    </gazebo>

    <gazebo reference="${robot_name}_joint_3">
      <provideFeedback>true</provideFeedback>
    </gazebo>
    <gazebo>
      <plugin name="ft_sensor_plugin" filename="libgazebo_ros_ft_sensor.so">
        <updateRate>100</updateRate>
        <topicName>ft_sensor/joint_3</topicName>
        <gaussianNoise>0.0</gaussianNoise>
        <jointName>${robot_name}_joint_3</jointName>
      </plugin>
    </gazebo>

    <gazebo reference="${robot_name}_joint_4">
      <provideFeedback>true</provideFeedback>
    </gazebo>
    <gazebo>
      <plugin name="ft_sensor_plugin" filename="libgazebo_ros_ft_sensor.so">
        <updateRate>100</updateRate>
        <topicName>ft_sensor/joint_4</topicName>
        <gaussianNoise>0.0</gaussianNoise>
        <jointName>${robot_name}_joint_4</jointName>
      </plugin>
    </gazebo>

    <gazebo reference="${robot_name}_joint_5">
      <provideFeedback>true</provideFeedback>
    </gazebo>
    <gazebo>
      <plugin name="ft_sensor_plugin" filename="libgazebo_ros_ft_sensor.so">
        <updateRate>100</updateRate>
        <topicName>ft_sensor/joint_5</topicName>
        <gaussianNoise>0.0</gaussianNoise>
        <jointName>${robot_name}_joint_5</jointName>
      </plugin>
    </gazebo>

    <gazebo reference="${robot_name}_joint_6">
      <provideFeedback>true</provideFeedback>
    </gazebo>
    <gazebo>
      <plugin name="ft_sensor_plugin" filename="libgazebo_ros_ft_sensor.so">
        <updateRate>100</updateRate>
        <topicName>ft_sensor/joint_6</topicName>
        <gaussianNoise>0.0</gaussianNoise>
        <jointName>${robot_name}_joint_6</jointName>
      </plugin>
    </gazebo>

    <gazebo reference="${robot_name}_joint_7">
      <provideFeedback>true</provideFeedback>
    </gazebo>
    <gazebo>
      <plugin name="ft_sensor_plugin" filename="libgazebo_ros_ft_sensor.so">
        <updateRate>100</updateRate>
        <topicName>ft_sensor/joint_7</topicName>
        <gaussianNoise>0.0</gaussianNoise>
        <jointName>${robot_name}_joint_7</jointName>
      </plugin>
    </gazebo>-->

    <!--Extensions -->
    <xacro:iiwa_gazebo robot_name="${robot_name}" />
    <xacro:iiwa_transmission hardware_interface="${hardware_interface}"/>

  </xacro:macro>

</robot>
